Workbook

Sheet Dashboard
B3: HDFC Focused 30 Fund Direct-Growth
B6: Fund Name | C6: =B3 -> HDFC Focused 30 Fund Direct-Growth | I6: Peer Comparison Graphs | Q6: Asset Allocation ( From ET Money)
B7: AMC Name | C7: HDFC
B8: Fund Type | C8: Equity
B9: Category | C9: Equity Focused
B10: Plan | C10: Direct
B11: Option | C11: Growth
B12: Inception Date | C12: 41275
B13: Date of Analysis | C13: 45780
B14: Analyst | C14: Chinmay C K
B16: Performance
B18: Return | C18: 1 Yr | D18: 3 Yr | E18: 5 Yr | F18: 10 Yr
B19: Trailing Return % | C19: 0.1675 | D19: 0.2615 | E19: 0.3267 | F19: 0.1552
B20: Rolling Return % | C20: 0.188 | D20: 0.172 | E20: 0.161 | F20: 0.177
B21: Absolute Return % | C21: =(1+C19)^1-1 -> 0.1675 | D21: =(1+D19)^3-1 -> 1.0075287 | E21: =(1+E19)^5-1 -> 3.1102065 | F21: =(1+F19)^10-1 -> 3.2322548
B23: Risk & Ratio Summary
B24: Benchmark | C24: Nifty 500 TRI
B25: Alpha | C25: 10.27
B26: Beta | C26: 0.75
B27: Sharpe ratio | C27: 1.49
B28: Treynor Ratio | C28: 0.21
B29: Standard Deviation | C29: 11.43
B30: Expense Ratio | C30: 0.0081
B31: Turnover Ratio | C31: 0.3073
B33: SIP Analysis
B34: SIP Start Date | C34: 43955
B35: Monthly Amount | C35: 60.86
B36: Total Amount Invested | C36: =-1*SUM(D46:D106) -> 305000
B37: Current Value | C37: =G106*C106 -> 589284.52
B38: XIRR (%) | C38: =XIRR(D46:D107,B46:B107) -> 0.27071207
B39: Total Returns % | C39: =C37/C36-1 -> 0.93208041
B43: SIP Analysis
B45: Date | C45: NAV | D45: SIP | E45: NAV Allocated | G45: Total NAV
B46: 43955 | C46: =INDEX(Sheet1!$1:$1048576,MATCH(Dashboard!B46,Sheet1!E:E,0),2) -> 60.864 | D46: -5000 | E46: =-1*D46/C46 -> 82.150368 | G46: =E46 -> 82.150368
B47: 43986 | C47: =INDEX(Sheet1!$1:$1048576,MATCH(Dashboard!B47,Sheet1!E:E,0),2) -> 64.221 | D47: -5000 | E47: =-1*D47/C47 -> 77.856153 | G47: =G46+E47 -> 160.00652
B48: 44018 | C48: =INDEX(Sheet1!$1:$1048576,MATCH(Dashboard!B48,Sheet1!E:E,0),2) -> 70.15 | D48: -5000 | E48: =-1*D48/C48 -> 71.275837 | G48: =G47+E48 -> 231.28236
B49: 44047 | C49: =INDEX(Sheet1!$1:$1048576,MATCH(Dashboard!B49,Sheet1!E:E,0),2) -> 71.009 | D49: -5000 | E49: =-1*D49/C49 -> 70.41361 | G49: =SUM(E$46:E49) -> 301.69597
B50: 44078 | C50: =INDEX(Sheet1!$1:$1048576,MATCH(Dashboard!B50,Sheet1!E:E,0),2) -> 72.377 | D50: -5000 | E50: =-1*D50/C50 -> 69.08272 | G50: =SUM(E$46:E50) -> 370.77869
B51: 44109 | C51: =INDEX(Sheet1!$1:$1048576,MATCH(Dashboard!B51,Sheet1!E:E,0),2) -> 70.902 | D51: -5000 | E51: =-1*D51/C51 -> 70.519873 | G51: =SUM(E$46:E51) -> 441.29856
B52: 44139 | C52: =INDEX(Sheet1!$1:$1048576,MATCH(Dashboard!B52,Sheet1!E:E,0),2) -> 71.93 | D52: -5000 | E52: =-1*D52/C52 -> 69.512026 | G52: =SUM(E$46:E52) -> 510.81059
...

Sheet Sheet1
B2: NAV
B3: 60.864 | E3: 43955 | G3: Industry Average
B4: 60.864 | E4: 43955 | G4: Return | H4: 1 Yr | I4: 3 Yr | J4: 5 Yr | K4: 10 Yr
B5: 60.653 | E5: 43956 | G5: Trailing Return % | H5: 0.072 | I5: 0.1779 | J5: 0.2415 | K5: 0.1407
B6: 60.653 | E6: 43956 | G6: Rolling Return % | H6: 0.133 | I6: 0.156 | J6: 0.153 | K6: 0.143
B7: 60.585 | E7: 43957 | G7: Absolute Return % | H7: =(1+H5)^1-1 -> 0.072 | I7: =(1+I5)^3-1 -> 0.63427548 | J7: =(1+J5)^5-1 -> 1.9493996 | K7: =(1+K5)^10-1 -> 2.730048
B8: 60.585 | E8: 43957
B9: 59.913 | E9: 43958 | G9: Risk & Ratio Summary
B10: 59.913 | E10: 43958 | G10: Benchmark | H10: Nifty 500 TRI
B11: 59.733 | E11: 43959 | G11: Alpha | H11: 5.7
B12: 59.733 | E12: 43959 | G12: Beta | H12: 1.01
B13: 59.533 | E13: 43962 | G13: Sharpe ratio | H13: 0.68
B14: 59.533 | E14: 43962 | G14: Treynor Ratio | H14: 0.1
B15: 59.418 | E15: 43963 | G15: Standard Deviation | H15: 13.6
B16: 59.418 | E16: 43963
B17: 60.862 | E17: 43964
B18: 60.862 | E18: 43964
B19: 59.487 | E19: 43965
B20: 59.487 | E20: 43965
B21: 59.63 | E21: 43966
B22: 59.63 | E22: 43966
B23: 57.534 | E23: 43969
B24: 57.534 | E24: 43969
B25: 57.477 | E25: 43970
B26: 57.477 | E26: 43970
B27: 58.66 | E27: 43971
... B1275: 250.21 | E1275: 45779
